<?xml version="1.0" ?>
<robot name="custom_amr" xmlns:xacro="http://ros.org/wiki/xacro">
  <xacro:include filename="$(find amr_description)/urdf/common_properties.xacro"/>
  <xacro:include filename="$(find amr_description)/urdf/amr_description.gazebo.xacro"/>

  <link name="base_footprint"/>

  <joint name="base_joint" type="fixed">
    <origin xyz="0.0 0.0 0.08" rpy="0.0 0.0 0.0"/>
    <parent link="base_footprint"/>
    <child link="base_link"/>
  </joint>

  <link
    name="base_link">
    <inertial>
      <origin
        xyz="-0.0139819427437898 0 0.196481873114789"
        rpy="0 0 0" />
      <mass
        value="240.871653090349" />
      <inertia
        ixx="7.41511315187009"
        ixy="1.96472545780946E-15"
        ixz="-0.190504509804657"
        iyy="8.82522019933863"
        iyz="1.00445313797886E-16"
        izz="11.8825659440432" />
    </inertial>
    <visual>
      <origin
        xyz="0 0 0"
        rpy="0 0 0" />
      <geometry>
        <mesh
          filename="package://amr_description/meshes/base_link.STL" />
      </geometry>
      <material
        name="">
        <color
          rgba="0.898039215686275 0.917647058823529 0.929411764705882 1" />
      </material>
    </visual>
    <collision>
      <origin
        xyz="0 0 0"
        rpy="0 0 0" />
      <geometry>
        <mesh
          filename="package://amr_description/meshes/base_link.STL" />
      </geometry>
    </collision>
  </link>
<!-- Left Wheels -->
<joint
name="left_wheel_joint"
type="continuous">
<origin
  xyz="0 0.295 -0.000168290822622486"
  rpy="0 0 0" />
<parent
  link="base_link" />
<child
  link="left_wheel" />
<axis
  xyz="0 1 0" />
</joint>

  <link
    name="left_wheel">
    <inertial>
      <origin
        xyz="-5.55111512312578E-17 -0.000574712643678116 0"
        rpy="0 0 0" />
      <mass
        value="1.02494460323367" />
      <inertia
        ixx="0.00183849946005578"
        ixy="2.56637004041976E-19"
        ixz="6.63260987832101E-22"
        iyy="0.0032231268004275"
        iyz="-2.35172790845663E-21"
        izz="0.00183849946005578" />
    </inertial>
    <visual>
      <origin
        xyz="0 0 0"
        rpy="0 0 0" />
      <geometry>
        <mesh
          filename="package://amr_description/meshes/left_wheel.STL" />
      </geometry>
      <material
        name="">
        <color
          rgba="0.298039215686275 0.298039215686275 0.298039215686275 1" />
      </material>
    </visual>
    <collision>
      <origin
        xyz="0 0 0"
        rpy="0 0 0" />
      <geometry>
        <mesh
          filename="package://amr_description/meshes/left_wheel.STL" />
      </geometry>
    </collision>
  </link>
  
<!-- Right Wheel -->
<joint
name="right_wheel_joint"
type="continuous">
<origin
  xyz="0 -0.295 -0.000168290822622486"
  rpy="0 0 0" />
<parent
  link="base_link" />
<child
  link="right_wheel" />
<axis
  xyz="0 1 0" />
</joint>

  <link
    name="right_wheel">
    <inertial>
      <origin
        xyz="0 0.000574712643678033 0"
        rpy="0 0 0" />
      <mass
        value="1.02494460323367" />
      <inertia
        ixx="0.00183849946005574"
        ixy="2.53679317773136E-19"
        ixz="-2.77800336919809E-20"
        iyy="0.0032231268004275"
        iyz="2.72448212357285E-20"
        izz="0.00183849946005574" />
    </inertial>
    <visual>
      <origin
        xyz="0 0 0"
        rpy="0 0 0" />
      <geometry>
        <mesh
          filename="package://amr_description/meshes/right_wheel.STL" />
      </geometry>
      <material
        name="">
        <color
          rgba="0.298039215686275 0.298039215686275 0.298039215686275 1" />
      </material>
    </visual>
    <collision>
      <origin
        xyz="0 0 0"
        rpy="0 0 0" />
      <geometry>
        <mesh
          filename="package://amr_description/meshes/right_wheel.STL" />
      </geometry>
    </collision>
  </link>

<!-- Casters front, back, right, left-->

<link
    name="front_right_caster_link">
    <inertial>
      <origin
        xyz="0 0 0"
        rpy="0 0 0" />
      <mass
        value="0.165228138624738" />
      <inertia
        ixx="8.08068865461608E-05"
        ixy="4.79259162819995E-21"
        ixz="1.82505431197023E-35"
        iyy="0.000105849276306473"
        iyz="8.39342182092113E-20"
        izz="8.08068865461609E-05" />
    </inertial>
    <visual>
      <origin
        xyz="0 0 0"
        rpy="0 0 0" />
      <geometry>
        <mesh
          filename="package://amr_description/meshes/front_right_caster_link.STL" />
      </geometry>
      <material
        name="">
        <color
          rgba="0.792156862745098 0.819607843137255 0.933333333333333 1" />
      </material>
    </visual>
    <collision>
      <origin
        xyz="0 0 0"
        rpy="0 0 0" />
      <geometry>
        <mesh
          filename="package://amr_description/meshes/front_right_caster_link.STL" />
      </geometry>
    </collision>
  </link>
  <joint
    name="front_right_caster_joint"
    type="fixed">
    <origin
      xyz="0.24 -0.170500000000001 -0.0451682908226246"
      rpy="0 0 0" />
    <parent
      link="base_link" />
    <child
      link="front_right_caster_link" />
    <axis
      xyz="0 0 0" />
  </joint>
  <link
    name="front_left_caster_link">
    <inertial>
      <origin
        xyz="0 -5.55111512312578E-17 -2.77555756156289E-17"
        rpy="0 0 0" />
      <mass
        value="0.165228138624738" />
      <inertia
        ixx="8.08068865461611E-05"
        ixy="7.41309980876794E-21"
        ixz="-5.57366493454268E-37"
        iyy="0.000105849276306473"
        iyz="8.39342182092112E-20"
        izz="8.08068865461611E-05" />
    </inertial>
    <visual>
      <origin
        xyz="0 0 0"
        rpy="0 0 0" />
      <geometry>
        <mesh
          filename="package://amr_description/meshes/front_left_caster_link.STL" />
      </geometry>
      <material
        name="">
        <color
          rgba="0.792156862745098 0.819607843137255 0.933333333333333 1" />
      </material>
    </visual>
    <collision>
      <origin
        xyz="0 0 0"
        rpy="0 0 0" />
      <geometry>
        <mesh
          filename="package://amr_description/meshes/front_left_caster_link.STL" />
      </geometry>
    </collision>
  </link>
  <joint
    name="front_left_caster_joint"
    type="fixed">
    <origin
      xyz="0.24 0.170499999999999 -0.0451682908226234"
      rpy="0 0 0" />
    <parent
      link="base_link" />
    <child
      link="front_left_caster_link" />
    <axis
      xyz="0 0 0" />
  </joint>
  <link
    name="back_right_caster_link">
    <inertial>
      <origin
        xyz="0 0 0"
        rpy="0 0 0" />
      <mass
        value="0.165228138624738" />
      <inertia
        ixx="8.08068865461608E-05"
        ixy="4.63377295058926E-21"
        ixz="1.518460617739E-35"
        iyy="0.000105849276306473"
        iyz="8.2067080220647E-20"
        izz="8.08068865461608E-05" />
    </inertial>
    <visual>
      <origin
        xyz="0 0 0"
        rpy="0 0 0" />
      <geometry>
        <mesh
          filename="package://amr_description/meshes/back_right_caster_link.STL" />
      </geometry>
      <material
        name="">
        <color
          rgba="0.792156862745098 0.819607843137255 0.933333333333333 1" />
      </material>
    </visual>
    <collision>
      <origin
        xyz="0 0 0"
        rpy="0 0 0" />
      <geometry>
        <mesh
          filename="package://amr_description/meshes/back_right_caster_link.STL" />
      </geometry>
    </collision>
  </link>
  <joint
    name="back_right_caster_joint"
    type="fixed">
    <origin
      xyz="-0.24 -0.1695 -0.0451682908226246"
      rpy="0 0 0" />
    <parent
      link="base_link" />
    <child
      link="back_right_caster_link" />
    <axis
      xyz="0 0 0" />
  </joint>
  <link
    name="back_left_caster_link">
    <inertial>
      <origin
        xyz="0 -5.55111512312578E-17 -2.77555756156289E-17"
        rpy="0 0 0" />
      <mass
        value="0.165228138624738" />
      <inertia
        ixx="8.08068865461611E-05"
        ixy="4.63377295058926E-21"
        ixz="1.4714408437061E-35"
        iyy="0.000105849276306473"
        iyz="7.95259813788841E-20"
        izz="8.08068865461611E-05" />
    </inertial>
    <visual>
      <origin
        xyz="0 0 0"
        rpy="0 0 0" />
      <geometry>
        <mesh
          filename="package://amr_description/meshes/back_left_caster_link.STL" />
      </geometry>
      <material
        name="">
        <color
          rgba="0.792156862745098 0.819607843137255 0.933333333333333 1" />
      </material>
    </visual>
    <collision>
      <origin
        xyz="0 0 0"
        rpy="0 0 0" />
      <geometry>
        <mesh
          filename="package://amr_description/meshes/back_left_caster_link.STL" />
      </geometry>
    </collision>
  </link>
  <joint
    name="back_left_caster_joint"
    type="fixed">
    <origin
      xyz="-0.24 0.1705 -0.0451682908226234"
      rpy="0 0 0" />
    <parent
      link="base_link" />
    <child
      link="back_left_caster_link" />
    <axis
      xyz="0 0 0" />
  </joint>

  <!-- Sensors Lasers and IMU link and joints -->

  <link
    name="laser_link">
    <inertial>
      <origin
        xyz="0 0 0.000306122448979651"
        rpy="0 0 0" />
      <mass
        value="0.471050402479253" />
      <inertia
        ixx="0.00044144544382281"
        ixy="1.20370621524202E-35"
        ixz="-1.66168069770557E-36"
        iyy="0.00044144544382281"
        iyz="-1.14537506940206E-21"
        izz="0.000600348931323048" />
    </inertial>
    <visual>
      <origin
        xyz="0 0 0"
        rpy="0 0 0" />
      <geometry>
        <mesh
          filename="package://amr_description/meshes/laser_link.STL" />
      </geometry>
      <material
        name="">
        <color
          rgba="0.250980392156863 0.250980392156863 0.250980392156863 1" />
      </material>
    </visual>
    <collision>
      <origin
        xyz="0 0 0"
        rpy="0 0 0" />
      <geometry>
        <mesh
          filename="package://amr_description/meshes/laser_link.STL" />
      </geometry>
    </collision>
  </link>
  <joint
    name="laser_joint"
    type="fixed">
    <origin
      xyz="0.27 0 0.104831709177377"
      rpy="0 0 0" />
    <parent
      link="base_link" />
    <child
      link="laser_link" />
    <axis
      xyz="0 0 0" />
  </joint>
  <link
    name="imu_link">
    <inertial>
      <origin
        xyz="0 0 0.000129053354769315"
        rpy="0 0 0" />
      <mass
        value="0.00775944693666731" />
      <inertia
        ixx="3.34029369368266E-07"
        ixy="2.68839162291071E-21"
        ixz="-8.24720213736489E-21"
        iyy="1.15002936936827E-06"
        iyz="-1.11138179153354E-21"
        izz="1.35499308670834E-06" />
    </inertial>
    <visual>
      <origin
        xyz="0 0 0"
        rpy="0 0 0" />
      <geometry>
        <mesh
          filename="package://amr_description/meshes/imu_link.STL" />
      </geometry>
      <material
        name="">
        <color
          rgba="0.250980392156863 0.250980392156863 0.250980392156863 1" />
      </material>
    </visual>
    <collision>
      <origin
        xyz="0 0 0"
        rpy="0 0 0" />
      <geometry>
        <mesh
          filename="package://amr_description/meshes/imu_link.STL" />
      </geometry>
    </collision>
  </link>
  <joint
    name="imu_joint"
    type="fixed">
    <origin
      xyz="0.259999999999996 0 0.354831709177378"
      rpy="0 0 0" />
    <parent
      link="base_link" />
    <child
      link="imu_link" />
    <axis
      xyz="0 0 0" />
  </joint>


</robot>