<?xml version="1.0" encoding="utf-8"?>

<robot
  name="custom_amr">
  
  <!-- LINKS AND JOINTS (With sensor links and sensor joints)-->
  <link name="base_footprint">
    
  </link>
  
  <link
    name="base_link">
    <inertial>
      <origin
        xyz="-0.013949 0 -0.15385"
        rpy="0 0 0" />
      <mass
        value="241.44" />
      <inertia
        ixx="7.4412"
        ixy="1.9468E-15"
        ixz="-0.18882"
        iyy="8.8511"
        iyz="1.2162E-16"
        izz="11.883" />
    </inertial>
    <visual>
      <origin
        xyz="0 0 0"
        rpy="0 0 0" />
      <geometry>
        <mesh
          filename="package://amr_description/meshes/base_link.STL" />
      </geometry>
      <material
        name="">
        <color
          rgba="0.89804 0.91765 0.92941 1" />
      </material>
    </visual>
    <collision>
      <origin
        xyz="0 0 0"
        rpy="0 0 0" />
      <geometry>
        <mesh
          filename="package://amr_description/meshes/base_link.STL" />
      </geometry>
    </collision>
  </link>
  
  <joint name="base_joint" type="fixed">
    <origin xyz="0.0 0.0 0.43" rpy="0.0 0.0 0.0"/>
    <parent link="base_footprint"/>
    <child link="base_link"/>
  </joint>
  
  <link
    name="left_wheel">
    <inertial>
      <origin
        xyz="-5.5511E-17 -0.00057471 0"
        rpy="0 0 0" />
      <mass
        value="1.0249" />
      <inertia
        ixx="0.0018385"
        ixy="2.5664E-19"
        ixz="6.6326E-22"
        iyy="0.0032231"
        iyz="-2.3517E-21"
        izz="0.0018385" />
    </inertial>
    <visual>
      <origin
        xyz="0 0 0"
        rpy="0 0 0" />
      <geometry>
        <mesh
          filename="package://amr_description/meshes/left_wheel.STL" />
      </geometry>
      <material
        name="">
        <color
          rgba="0.29804 0.29804 0.29804 1" />
      </material>
    </visual>
    <collision>
      <origin
        xyz="0 0 0"
        rpy="0 0 0" />
      <geometry>
        <mesh
          filename="package://amr_description/meshes/left_wheel.STL" />
      </geometry>
    </collision>
  </link>


  <joint
    name="left_wheel_joint"
    type="continuous">
    <origin
      xyz="0 0.295 -0.35"
      rpy="0 0 0" />
    <parent
      link="base_link" />
    <child
      link="left_wheel" />
    <axis
      xyz="0 1 0" />
  </joint>


  <link
    name="right_wheel">
    <inertial>
      <origin
        xyz="0 0.00057471 2.7756E-17"
        rpy="0 0 0" />
      <mass
        value="1.0249" />
      <inertia
        ixx="0.0018385"
        ixy="2.5368E-19"
        ixz="-2.778E-20"
        iyy="0.0032231"
        iyz="2.7245E-20"
        izz="0.0018385" />
    </inertial>
    <visual>
      <origin
        xyz="0 0 0"
        rpy="0 0 0" />
      <geometry>
        <mesh
          filename="package://amr_description/meshes/right_wheel.STL" />
      </geometry>
      <material
        name="">
        <color
          rgba="0.29804 0.29804 0.29804 1" />
      </material>
    </visual>
    <collision>
      <origin
        xyz="0 0 0"
        rpy="0 0 0" />
      <geometry>
        <mesh
          filename="package://amr_description/meshes/right_wheel.STL" />
      </geometry>
    </collision>
  </link>

  
  <joint
    name="right_wheel_joint"
    type="continuous">
    <origin
      xyz="0 -0.295 -0.35"
      rpy="0 0 0" />
    <parent
      link="base_link" />
    <child
      link="right_wheel" />
    <axis
      xyz="0 1 0" />
  </joint>
  <link
    name="front_right_caster_link">
    <inertial>
      <origin
        xyz="0 0 0"
        rpy="0 0 0" />
      <mass
        value="0.16523" />
      <inertia
        ixx="8.0807E-05"
        ixy="4.7926E-21"
        ixz="1.8251E-35"
        iyy="0.00010585"
        iyz="8.3934E-20"
        izz="8.0807E-05" />
    </inertial>
    <visual>
      <origin
        xyz="0 0 0"
        rpy="0 0 0" />
      <geometry>
        <mesh
          filename="package://amr_description/meshes/front_right_caster_link.STL" />
      </geometry>
      <material
        name="">
        <color
          rgba="0.79216 0.81961 0.93333 1" />
      </material>
    </visual>
    <collision>
      <origin
        xyz="0 0 0"
        rpy="0 0 0" />
      <geometry>
        <mesh
          filename="package://amr_description/meshes/front_right_caster_link.STL" />
      </geometry>
    </collision>
  </link>
  <joint
    name="front_right_caster_joint"
    type="fixed">
    <origin
      xyz="0.24 -0.1705 -0.395"
      rpy="0 0 0" />
    <parent
      link="base_link" />
    <child
      link="front_right_caster_link" />
    <axis
      xyz="0 0 0" />
  </joint>
  <link
    name="front_left_caster_link">
    <inertial>
      <origin
        xyz="0 -5.5511E-17 -2.7756E-17"
        rpy="0 0 0" />
      <mass
        value="0.16523" />
      <inertia
        ixx="8.0807E-05"
        ixy="7.4131E-21"
        ixz="-5.5737E-37"
        iyy="0.00010585"
        iyz="8.3934E-20"
        izz="8.0807E-05" />
    </inertial>
    <visual>
      <origin
        xyz="0 0 0"
        rpy="0 0 0" />
      <geometry>
        <mesh
          filename="package://amr_description/meshes/front_left_caster_link.STL" />
      </geometry>
      <material
        name="">
        <color
          rgba="0.79216 0.81961 0.93333 1" />
      </material>
    </visual>
    <collision>
      <origin
        xyz="0 0 0"
        rpy="0 0 0" />
      <geometry>
        <mesh
          filename="package://amr_description/meshes/front_left_caster_link.STL" />
      </geometry>
    </collision>
  </link>
  <joint
    name="front_left_caster_joint"
    type="fixed">
    <origin
      xyz="0.24 0.1705 -0.395"
      rpy="0 0 0" />
    <parent
      link="base_link" />
    <child
      link="front_left_caster_link" />
    <axis
      xyz="0 0 0" />
  </joint>
  <link
    name="back_right_caster_link">
    <inertial>
      <origin
        xyz="0 0 0"
        rpy="0 0 0" />
      <mass
        value="0.16523" />
      <inertia
        ixx="8.0807E-05"
        ixy="4.6338E-21"
        ixz="1.5185E-35"
        iyy="0.00010585"
        iyz="8.2067E-20"
        izz="8.0807E-05" />
    </inertial>
    <visual>
      <origin
        xyz="0 0 0"
        rpy="0 0 0" />
      <geometry>
        <mesh
          filename="package://amr_description/meshes/back_right_caster_link.STL" />
      </geometry>
      <material
        name="">
        <color
          rgba="0.79216 0.81961 0.93333 1" />
      </material>
    </visual>
    <collision>
      <origin
        xyz="0 0 0"
        rpy="0 0 0" />
      <geometry>
        <mesh
          filename="package://amr_description/meshes/back_right_caster_link.STL" />
      </geometry>
    </collision>
  </link>
  <joint
    name="back_right_caster_joint"
    type="fixed">
    <origin
      xyz="-0.24 -0.1695 -0.395"
      rpy="0 0 0" />
    <parent
      link="base_link" />
    <child
      link="back_right_caster_link" />
    <axis
      xyz="0 0 0" />
  </joint>
  <link
    name="back_left_caster_link">
    <inertial>
      <origin
        xyz="0 -5.5511E-17 -2.7756E-17"
        rpy="0 0 0" />
      <mass
        value="0.16523" />
      <inertia
        ixx="8.0807E-05"
        ixy="4.6338E-21"
        ixz="1.4714E-35"
        iyy="0.00010585"
        iyz="7.9526E-20"
        izz="8.0807E-05" />
    </inertial>
    <visual>
      <origin
        xyz="0 0 0"
        rpy="0 0 0" />
      <geometry>
        <mesh
          filename="package://amr_description/meshes/back_left_caster_link.STL" />
      </geometry>
      <material
        name="">
        <color
          rgba="0.79216 0.81961 0.93333 1" />
      </material>
    </visual>
    <collision>
      <origin
        xyz="0 0 0"
        rpy="0 0 0" />
      <geometry>
        <mesh
          filename="package://amr_description/meshes/back_left_caster_link.STL" />
      </geometry>
    </collision>
  </link>
  <joint
    name="back_left_caster_joint"
    type="fixed">
    <origin
      xyz="-0.24 0.1705 -0.395"
      rpy="0 0 0" />
    <parent
      link="base_link" />
    <child
      link="back_left_caster_link" />
    <axis
      xyz="0 0 0" />
  </joint>
  <link
    name="laser_link">
    <inertial>
      <origin
        xyz="0 0 0.00030612"
        rpy="0 0 0" />
      <mass
        value="0.47105" />
      <inertia
        ixx="0.00044145"
        ixy="1.2037E-35"
        ixz="-1.6617E-36"
        iyy="0.00044145"
        iyz="-1.1454E-21"
        izz="0.00060035" />
    </inertial>
    <visual>
      <origin
        xyz="0 0 0"
        rpy="0 0 0" />
      <geometry>
        <mesh
          filename="package://amr_description/meshes/laser_link.STL" />
      </geometry>
      <material
        name="">
        <color
          rgba="0.25098 0.25098 0.25098 1" />
      </material>
    </visual>
    <collision>
      <origin
        xyz="0 0 0"
        rpy="0 0 0" />
      <geometry>
        <mesh
          filename="package://amr_description/meshes/laser_link.STL" />
      </geometry>
    </collision>
  </link>
  <joint
    name="laser_joint"
    type="fixed">
    <origin
      xyz="0.27 0 -0.245"
      rpy="0 0 0" />
    <parent
      link="base_link" />
    <child
      link="laser_link" />
    <axis
      xyz="0 0 0" />
  </joint>
  <link
    name="imu_link">
    <inertial>
      <origin
        xyz="0 0 0"
        rpy="0 0 0" />
      <mass
        value="0" />
      <inertia
        ixx="0"
        ixy="0"
        ixz="0"
        iyy="0"
        iyz="0"
        izz="0" />
    </inertial>
    <visual>
      <origin
        xyz="0 0 0"
        rpy="0 0 0" />
      <geometry>
        <mesh
          filename="package://amr_description/meshes/imu_link.STL" />
      </geometry>
      <material
        name="">
        <color
          rgba="1 1 1 1" />
      </material>
    </visual>
    <collision>
      <origin
        xyz="0 0 0"
        rpy="0 0 0" />
      <geometry>
        <mesh
          filename="package://amr_description/meshes/imu_link.STL" />
      </geometry>
    </collision>
  </link>
  <joint
    name="imu_joint"
    type="fixed">
    <origin
      xyz="0.26 0 0.005"
      rpy="0 0 0" />
    <parent
      link="base_link" />
    <child
      link="imu_link" />
    <axis
      xyz="0 0 0" />
  </joint>

<!-- Sensor Descriptions -->

<!-- Laser Scanner -->
<gazebo reference="laser_link">
  <sensor type="ray" name="LDS_01">
    <pose>0 0 0 0 0 0</pose>
    <visualize>true</visualize>
    <update_rate>40</update_rate>
    <ray>
      <scan>
        <horizontal>
          <samples>720</samples>
          <resolution>1</resolution>
          <min_angle>-1.5708</min_angle>
          <max_angle>1.5708</max_angle>
        </horizontal>
      </scan>
      <range>
        <min>0.10</min>
        <max>30.0</max>
        <resolution>0.01</resolution>
      </range>
      <noise>
        <type>gaussian</type>
        <!-- Noise parameters based on published spec for Hokuyo laser
             achieving "+-30mm" accuracy at range < 10m.  A mean of 0.0m and
             stddev of 0.01m will put 99.7% of samples within 0.03m of the true
             reading. -->
        <mean>0.0</mean>
        <stddev>0.01</stddev>
      </noise>
    </ray>
    <plugin name="gazebo_ros_head_hokuyo_controller" filename="libgazebo_ros_laser.so">
      <topicName>/scan</topicName>
      <frameName>laser_link</frameName>
    </plugin>
  </sensor>
</gazebo>

<!-- IMU -->
<!-- <gazebo reference="imu_link">
  <gravity>true</gravity>
  <sensor name="imu_sensor" type="imu">
    <always_on>true</always_on>
    <update_rate>100</update_rate>
    <visualize>true</visualize>
    <topic>__default_topic__</topic>
    <plugin filename="libgazebo_ros_imu_sensor.so" name="imu_plugin">
      <topicName>imu</topicName>
      <bodyName>imu_link</bodyName>
      <updateRateHZ>10.0</updateRateHZ>
      <gaussianNoise>0.0</gaussianNoise>
      <xyzOffset>0 0 0</xyzOffset>
      <rpyOffset>0 0 0</rpyOffset>
      <frameName>imu_link</frameName>
      <initialOrientationAsReference>false</initialOrientationAsReference>
    </plugin>
    <pose>0 0 0 0 0 0</pose>
  </sensor>
</gazebo>
-->

<!-- Differential Drive Plugin -->
<gazebo>
  <plugin name="differential_drive_controller" filename="libgazebo_ros_diff_drive.so">

    <!-- Plugin update rate in Hz -->
    <updateRate>30</updateRate>

    <!-- Name of left joint, defaults to `left_joint` -->
    <leftJoint>left_wheel_joint</leftJoint>

    <!-- Name of right joint, defaults to `right_joint` -->
    <rightJoint>right_wheel_joint</rightJoint>

    <!-- The distance from the center of one wheel to the other, in meters, defaults to 0.34 m -->
    <wheelSeparation>0.590</wheelSeparation>

    <!-- Diameter of the wheels, in meters, defaults to 0.15 m -->
    <wheelDiameter>0.160</wheelDiameter>

    <!-- Wheel acceleration, in rad/s^2, defaults to 0.0 rad/s^2 -->
    <wheelAcceleration>1.0</wheelAcceleration>

    <!-- Maximum torque which the wheels can produce, in Nm, defaults to 5 Nm -->
    <wheelTorque>30</wheelTorque>

    <!-- Topic to receive geometry_msgs/Twist message commands, defaults to `cmd_vel` -->
    <commandTopic>cmd_vel</commandTopic>

    <!-- Topic to publish nav_msgs/Odometry messages, defaults to `odom` -->
    <odometryTopic>odom</odometryTopic>

    <!-- Odometry frame, defaults to `odom` -->
    <odometryFrame>odom</odometryFrame>

    <!-- Robot frame to calculate odometry from, defaults to `base_footprint` -->
    <robotBaseFrame>base_footprint</robotBaseFrame>

    <!-- Odometry source, 0 for ENCODER, 1 for WORLD, defaults to WORLD -->
    <odometrySource>1</odometrySource>

    <!-- Set to true to publish transforms for the wheel links, defaults to false -->
    <publishWheelTF>true</publishWheelTF>

    <!-- Set to true to publish transforms for the odometry, defaults to true -->
    <publishOdom>true</publishOdom>

    <!-- Set to true to publish sensor_msgs/JointState on /joint_states for the wheel joints, defaults to false -->
    <publishWheelJointState>true</publishWheelJointState>

    <!-- Set to true to swap right and left wheels, defaults to true -->
    <legacyMode>false</legacyMode>
  </plugin>
</gazebo>


<!-- ROS Control Plugin -->
<gazebo>
  <plugin name="gazebo_ros_control" filename="libgazebo_ros_control.so">
    <robotNamespace>/</robotNamespace>
    <controlPeriod>0.001</controlPeriod>
    <legacyModeNS>false</legacyModeNS>
  </plugin>
</gazebo>

<!-- Friction and Physics Properties-->
<gazebo reference="base_link">
  <mu1 value="1.0"/>
  <mu2 value="1.0"/>
  <kp value="10000000.0" />
  <kd value="1.0" />
  <fdir1 value="1 0 0"/>
 </gazebo>

<gazebo reference="left_wheel">
  <mu1 value="100.0"/>
  <mu2 value="100.0"/>
  <kp value="10000000.0" />
  <kd value="1.0" />
  <fdir1 value="1 0 0"/>
 </gazebo>
 
 <gazebo reference="right_wheel">
  <mu1 value="100.0"/>
  <mu2 value="100.0"/>
  <kp value="11000000.0" />
  <kd value="1.0" />
  <fdir1 value="1 0 0"/>
 </gazebo>
 
 <gazebo reference="front_right_caster_link">
  <mu1 value="0.1"/>
  <mu2 value="0.1"/>
  <kp value="1000000.0" />
  <kd value="1.0" />
  <fdir1 value="1 0 0"/>
 </gazebo>
 
 <gazebo reference="front_left_caster_link">
  <mu1 value="0.1"/>
  <mu2 value="0.1"/>
  <kp value="1000000.0" />
  <kd value="1.0" />
  <fdir1 value="1 0 0"/>
 </gazebo>

 <gazebo reference="back_left_caster_link">
  <mu1 value="0.1"/>
  <mu2 value="0.1"/>
  <kp value="1000000.0" />
  <kd value="1.0" />
  <fdir1 value="1 0 0"/>
 </gazebo>

 <gazebo reference="back_right_caster_link">
  <mu1 value="0.1"/>
  <mu2 value="0.1"/>
  <kp value="1000000.0" />
  <kd value="1.0" />
  <fdir1 value="1 0 0"/>
 </gazebo>

<!-- Materials --> 

</robot>